<?xml version="1.0"?>

<robot name="mobile_robot">
    <link name="base_link">
        <visual>
            <geometry>
                <box size="0.4 0.2 0.1"/>
            </geometry>
        </visual>
        <collision>
            <geometry>
                <box size="0.4 0.2 0.1"/>
            </geometry>
        </collision>
        <inertial>
            <mass value="5"/>
            <inertia ixx="0.020833" ixy="0.0" ixz="0.0" iyy="0.07083" iyz="0.0" izz="0.08333"/>
        </inertial>
    </link>

    <!-- Front Left Wheel -->
    <link name="front_left_wheel">
        <visual>
            <geometry>
                <cylinder length="0.05" radius="0.05"/>
            </geometry>
            <material name="black">
                <color rgba="0.0 0.0 0.0 1.0"/>
            </material>
        </visual>
        <collision>
            <geometry>
                <cylinder length="0.05" radius="0.05"/>
            </geometry>
        </collision>
        <inertial>
            <mass value="0.3"/>
            <inertia ixx="0.00025" ixy="0.0" ixz="0.0" iyy="0.00025" iyz="0.0" izz="0.000375"/>
        </inertial>
    </link>
    <joint name="front_left_wheel_joint" type="continuous">
        <parent link="base_link"/>
        <child link="front_left_wheel"/>
        <origin xyz="0.15 0.1 -0.05" rpy="0 1.57 0"/>
        <axis xyz="0 1 0"/>
    </joint>

    <!-- Front Right Wheel -->
    <link name="front_right_wheel">
        <visual>
            <geometry>
                <cylinder length="0.05" radius="0.05"/>
            </geometry>
            <material name="black">
                <color rgba="0.0 0.0 0.0 1.0"/>
            </material>
        </visual>
        <collision>
             <geometry>
                <cylinder length="0.05" radius="0.05"/>
            </geometry>
        </collision>
        <inertial>
            <mass value="0.3"/>
            <inertia ixx="0.00025" ixy="0.0" ixz="0.0" iyy="0.00025" iyz="0.0" izz="0.000375"/>
        </inertial>
    </link>
    <joint name="front_right_wheel_joint" type="continuous">
        <parent link="base_link"/>
        <child link="front_right_wheel"/>
        <origin xyz="0.15 -0.1 -0.05" rpy="0 1.57 0"/>
        <axis xyz="0 1 0"/>
    </joint>

    <!-- Rear Left Wheel -->
    <link name="rear_left_wheel">
        <visual>
            <geometry>
                <cylinder length="0.05" radius="0.05"/>
            </geometry>
            <material name="black">
                <color rgba="0.0 0.0 0.0 1.0"/>
            </material>
        </visual>
        <collision>
            <geometry>
                <cylinder length="0.05" radius="0.05"/>
            </geometry>
        </collision>
        <inertial>
            <mass value="0.3"/>
            <inertia ixx="0.00025" ixy="0.0" ixz="0.0" iyy="0.00025" iyz="0.0" izz="0.000375"/>
        </inertial>
    </link>
    <joint name="rear_left_wheel_joint" type="continuous">
        <parent link="base_link"/>
        <child link="rear_left_wheel"/>
        <origin xyz="-0.15 0.1 -0.05" rpy="0 1.57 0"/>
        <axis xyz="0 1 0"/>
    </joint>

    <!-- Rear Right Wheel -->
    <link name="rear_right_wheel">
        <visual>
            <geometry>
                <cylinder length="0.05" radius="0.05"/>
            </geometry>
            <material name="black">
                <color rgba="0.0 0.0 0.0 1.0"/>
            </material>
        </visual>
        <collision>
            <geometry>
                <cylinder length="0.05" radius="0.05"/>
            </geometry>
        </collision>
        <inertial>
            <mass value="0.3"/>
            <inertia ixx="0.00025" ixy="0.0" ixz="0.0" iyy="0.00025" iyz="0.0" izz="0.000375"/>
        </inertial>
    </link>
    <joint name="rear_right_wheel_joint" type="continuous">
        <parent link="base_link"/>
        <child link="rear_right_wheel"/>
        <origin xyz="-0.15 -0.1 -0.05" rpy="0 1.57 0"/>
        <axis xyz="0 1 0"/>
    </joint>
</robot>
