<?xml version="1.0"?>

<robot name="mobile_robot">
    <link name="base_link">
        <visual>
            <geometry>
                 <mesh filename="package://robile_robot/models/base_link.stl" scale="0.002 0.002 0.002"/>
            </geometry>
            <!-- <material name="gray">
                <color rgba="0.6 0.6 0.6 1.0"/>
            </material> -->
                      <origin xyz="-0.15 -0.18 0.0" rpy="1.57 0.0 1.57"/>
        </visual>
        <collision>
            
        </collision>
    </link>

    <!-- rear Left Wheel -->
    <link name="near_left_wheel">
        <visual>
            <geometry>
                <cylinder length="0.05" radius="0.05"/>
            </geometry>
            <material name="black">
                <color rgba="0.0 0.0 0.0 1.0"/>
            </material>
        </visual>
    </link>
    <joint name="near_left_wheel_joint" type="continuous">
        <parent link="base_link"/>
        <child link="near_left_wheel"/>
        <origin xyz="0.18 0.2 -0.01" rpy="0 1.57 0"/>
        <axis xyz="0 1 0"/>
    </joint>

    <!-- Front left Wheel -->
    <link name="front_left_wheel">
        <visual>
            <geometry>
                <cylinder length="0.05" radius="0.05"/>
            </geometry>
            <material name="black">
                <color rgba="0.0 0.0 0.0 1.0"/>
            </material>
        </visual>
    </link>
    <joint name="front_left_wheel_joint" type="continuous">
        <parent link="base_link"/>
        <child link="front_left_wheel"/>
        <origin xyz="0.18 -0.1 -0.01" rpy="0 1.57 0"/>
        <axis xyz="0 1 0"/>
    </joint>

    <!-- Rear Left Wheel -->
    <link name="rear_right_wheel">
        <visual>
            <geometry>
                <cylinder length="0.05" radius="0.05"/>
            </geometry>
            <material name="black">
                <color rgba="0.0 0.0 0.0 1.0"/>
            </material>
        </visual>
    </link>
    <joint name="rear_right_wheel_joint" type="continuous">
        <parent link="base_link"/>
        <child link="rear_right_wheel"/>
        <origin xyz="-0.18 0.2 -0.01" rpy="0 1.57 0"/>
        <axis xyz="0 1 0"/>
    </joint>

    <!-- Rear Right Wheel -->
    <link name="front_right_wheel">
        <visual>
            <geometry>
                <cylinder length="0.05" radius="0.05"/>
            </geometry>
            <material name="black">
                <color rgba="0.0 0.0 0.0 1.0"/>
            </material>
        </visual>
    </link>
    <joint name="rear_front_wheel_joint" type="continuous">
        <parent link="base_link"/>
        <child link="front_right_wheel"/>
        <origin xyz="-0.18 -0.1 -0.01" rpy="0 1.57 0"/>
        <axis xyz="0 1 0"/>
    </joint>
</robot>
