<?xml version="1.0"?>
<robot xmlns:xacro="http://ros.org/wiki/xacro" name="mobile_robot">
<xacro:include filename="$(find ur_description)/urdf/inc/ur5_macro.xacro"/>
<xacro:include filename="$(find ur_description)/urdf/inc/ur3_macro.xacro"/>
    <!-- Thân -->
  <link name="base_link">
    <visual>
      <geometry>
        <mesh filename="package://robile_robot/models/body3.stl"/>
      </geometry>
      <material name="pink">
        <color rgba="1 0.4 0.7 1"/>
      </material>
      <origin xyz="-0.3 0.5 0.1" rpy="1.57 0 0"/>
    </visual>
    <collision>
      <geometry>
        <mesh filename="package://robile_robot/models/body3.stl"/>
      </geometry>
    </collision>
    <inertial>
      <mass value="2"/>
      <inertia ixx="0.4465" ixy="0" ixz="0" iyy="0.3468" iyz="0.0" izz="0.4026"/>
    </inertial>
  </link>

<joint name="base_to_ur3_base" type="fixed">
    <parent link="base_link"/>
    <child link="ur3_base_link"/>  <!-- Kiểm tra lại tên của link này trong UR5 -->
    <origin xyz="0.1 -0.8 0.7" rpy="3.14 1.57 1.57"/>
  </joint>

<joint name="base_to_ur5_base" type="fixed">
    <parent link="base_link"/>
    <child link="ur5_base_link"/>  <!-- Kiểm tra lại tên của link này trong UR5 -->
    <origin xyz="0.1 0.5 0.7" rpy="0 1.57 1.57"/>
  </joint>

  <!-- Include UR5 -->
  <xacro:ur5_robot prefix="ur5_"/>
  <xacro:ur5_robot prefix="ur3_"/>
<!-- Bánh xe -->
  <link name="wheel_ph_trc">
    <visual>
      <geometry>
        <cylinder radius="0.2" length="0.2"/>
      </geometry>
      <material name="black">
        <color rgba="0 0 0 1"/>
      </material>
    </visual>
    <collision>
      <geometry>
        <cylinder radius="0.2" length="0.2"/>
      </geometry>
    </collision>
    <inertial>
      <mass value="1"/>
      <inertia ixx="0.013333" ixy="0.0" ixz="0.0" iyy="0.013333" iyz="0.0" izz="0.02"/>
    </inertial>
  </link>

  <link name="wheel_tr_trc">
    <visual>
      <geometry>
        <cylinder radius="0.2" length="0.2"/>
      </geometry>
      <material name="black">
        <color rgba="0 0 0 1"/>
      </material>
    </visual>
    <collision>
      <geometry>
        <cylinder radius="0.2" length="0.2"/>
      </geometry>
    </collision>
    <inertial>
      <mass value="1"/>
      <inertia ixx="0.013333" ixy="0.0" ixz="0.0" iyy="0.013333" iyz="0.0" izz="0.02"/>
    </inertial>
  </link>

  <link name="wheel_tr_s">
    <visual>
      <geometry>
        <cylinder radius="0.2" length="0.2"/>
      </geometry>
      <material name="black">
        <color rgba="0 0 0 1"/>
      </material>
    </visual>
    <collision>
      <geometry>
        <cylinder radius="0.2" length="0.2"/>
      </geometry>
    </collision>
    <inertial>
      <mass value="1"/>
      <inertia ixx="0.013333" ixy="0.0" ixz="0.0" iyy="0.013333" iyz="0.0" izz="0.02"/>
    </inertial>
  </link>

  <link name="wheel_ph_s">
    <visual>
      <geometry>
        <cylinder radius="0.2" length="0.2"/>
      </geometry>
      <material name="black">
        <color rgba="0 0 0 1"/>
      </material>
    </visual>
    <collision>
      <geometry>
        <cylinder radius="0.2" length="0.2"/>
      </geometry>
    </collision>
    <inertial>
      <mass value="1"/>
      <inertia ixx="0.013333" ixy="0.0" ixz="0.0" iyy="0.013333" iyz="0.0" izz="0.02"/>
    </inertial>
  </link>

  <gazebo>
    <plugin name="diff_drive" filename="libgazebo_ros_diff_drive.so">
    <ros>
  <namespace>/</namespace>
</ros>
        <!-- Joint Names -->
        <leftJoint>joint_wheel_tr_trc</leftJoint>
        <rightJoint>joint_wheel_ph_trc</rightJoint>
        <!-- <leftJoint>joint_wheel_tr_s</leftJoint>
        <rightJoint>joint_wheel_ph_s</rightJoint> -->

        <!-- Wheel Properties -->
        <wheelSeparation>0.25</wheelSeparation>
        <wheelDiameter>0.4</wheelDiameter>

        <!-- Control Topic -->

        <commandTopic>/cmd_vel</commandTopic>

        <!-- Odometry and Frames -->
        <odometryTopic>/odom</odometryTopic>
        <odometryFrame>odom</odometryFrame>
        <odometrySource>world</odometrySource>
        <robotBaseFrame>base_link</robotBaseFrame>

        <!-- Publish Options -->
        <publishOdomTF>true</publishOdomTF>
        <publishWheelTF>true</publishWheelTF>
        <publishTf>true</publishTf>
        <publishWheelJointState>true</publishWheelJointState>
        <!-- Wheel Dynamics -->
        <wheelAcceleration>200.0</wheelAcceleration>
        <wheelTorque>200.0</wheelTorque>
        <updateRate>100</updateRate>

        <rosDebugLevel>na</rosDebugLevel>
        
    </plugin>

</gazebo>

  <!-- Khớp nối bánh xe -->
  <joint name="joint_wheel_tr_trc" type="continuous">
    <parent link="base_link"/>
    <child link="wheel_tr_trc"/>
    <origin xyz="-0.3 -0.865 0.2" rpy="1.57 0 0"/>
    <axis xyz="0 0 1"/>
  </joint>

  <joint name="joint_wheel_ph_trc" type="continuous">
    <parent link="base_link"/>
    <child link="wheel_ph_trc"/>
    <origin xyz="-0.3 0.6 0.2" rpy="1.57 0 0"/>
    <axis xyz="0 0 1"/>
  </joint>

  <joint name="joint_wheel_ph_s" type="continuous">
    <parent link="base_link"/>
    <child link="wheel_ph_s"/>
    <origin xyz="0.7 0.6 0.2" rpy="1.57 0 0"/>
    <axis xyz="0 0 1"/>
  </joint>

  <joint name="joint_wheel_tr_s" type="continuous">
    <parent link="base_link"/>
    <child link="wheel_tr_s"/>
    <origin xyz="0.7 -0.865 0.2" rpy="1.57 0 0"/>
    <axis xyz="0 0 1"/>
  </joint>

  <!-- <camera> -->

<!-- Base Camera -->
<link name="camera_link">
        <visual>
            <geometry>
                <mesh filename="package://robile_robot/models/eye.stl" scale="0.5 0.5 0.5"/>
            </geometry>
            <origin xyz="-1.3 -0.8 -1.55" rpy="1.57 0 1.57"/>
        </visual>
        <inertial>

            <mass value="0.1"/>
            <inertia ixx="0.00004167" ixy="0.000" ixz="0.00" iyy="0.00007083" iyz="0.0" izz="0.00010417"/>

        </inertial>
    </link>
    <!-- Camera Joint -->
    <joint name="camera_joint" type="fixed">
        <parent link="base_link"/>
        <child link="camera_link"/>
        <origin xyz="-0.15 -0.40 1.45" rpy="0 0 3.14"/>
    </joint>
  <!-- Camera Work -->
    <gazebo reference="camera_link">
        <material>Gazebo/Red</material>
        <sensor name="camera" type="camera">
            <pose> 1.25 -0.4 2 0 0 0 </pose>
            <visualize>true</visualize>
            <update_rate>10</update_rate>
            <camera>
                <horizontal_fov>1.089</horizontal_fov>
                <image>
                    <format>R8G8B8</format>
                    <width>640</width>
                    <height>480</height>
                </image>
                <clip>
                    <near>0.05</near>
                    <far>8.0</far>
                </clip>
            </camera>
            <plugin name="camera_controller" filename="libgazebo_ros_camera.so">
                <frame_name>camera_link_optical</frame_name>
            </plugin>
        </sensor>
    </gazebo>

  <!-- Base Sensor -->
  <link name="base_scan">
    <visual>
      <origin xyz="0 0 0.0" rpy="0 0 0"/>
      <geometry>
        <cylinder length="0.1" radius="0.1"/>
      </geometry>
     <material name="green">
        <color rgba="0.0 1 0.0 1.0"/>
     </material>
    </visual>
    <collision>
      <origin xyz="0 0 0.3" rpy="0 0 0"/>
      <geometry>
        <cylinder length="0.1" radius="0.1"/>
      </geometry>
    </collision>
    <inertial>
      <mass value="0.1" />
      <origin xyz="0 0 0" />
      <inertia ixx="0.0003333" ixy="0.0" ixz="0.0"
               iyy="0.0003333" iyz="0.0"
               izz="0.0005" />
    </inertial>
  </link>
  
  <!-- Sensor Joint -->
  <joint name="scan_joint" type="fixed">
    <parent link="base_link"/>
    <child link="base_scan"/>
    <origin xyz="0 -0.17 1.57" rpy="0 0 0"/>
  </joint>

<!-- Sensor Work -->
<gazebo reference="base_scan">
    <material>Gazebo/FlatBlack</material>
    <sensor type="ray" name="lds_lfcd_sensor">
      <pose>0 0 0 0 0 0</pose>
      <visualize>true</visualize>
      <update_rate>5</update_rate>
      <ray>
        <scan>
          <horizontal>
            <samples>360</samples>
            <resolution>1</resolution>
            <min_angle>0</min_angle>
            <max_angle>6.28319</max_angle>
          </horizontal>
        </scan>
        <range>
          <min>0.120</min>
          <max>3.5</max>
          <resolution>0.015</resolution>
        </range>
        <noise>
          <type>gaussian</type>
          <mean>0.0</mean>
          <stddev>0.01</stddev>
        </noise>
      </ray>
      <plugin name="gazebo_ros_lds_lfcd_controller" filename="libgazebo_ros_laser.so">
        <topicName>scan</topicName>
        <frameName>base_scan</frameName>
      </plugin>
    </sensor>
  </gazebo>
 </robot>